Workbook

Sheet Data
B1: No | C1: Nama Perusahaan | D1: Tahun | E1: Kas | F1: Aktiva Lancar | G1: Total Aset | H1: Hutang Lancar | I1: Total Hutang | J1: Saldo Laba | K1: Total Ekuitas | L1: Pendapatan | M1: EBIT | N1: Laba Bersih | O1: Persentase Kepemilikan Terbesar | P1: Keterangan | Q1: Jumlah Komisaris Independen | R1: Jumlah Dewan Komisaris | S1: Jumlah Dewan Direksi | T1: Jumlah Dewan Komisaris dan Dewan Direksi | U1: Persentase Kepemilikan oleh Komisaris dan Direksi | V1: BoC Education [Bachelor + (2 x Master) + (2 x MBA) + (3 x PhD)] | W1: TMT Education (Dewan Komisaris) | X1: TMT Education (Dewan Direksi) [Bachelor + (2 x Master) + (2 x MBA) + (3 x PhD)] | Y1: Keterangan Data
A2: Asuransi Jiwa | B2: 1 | C2: Asuransi Jiwa Bersama Bumiputera 1912 | D2: 2014 | E2: 0 | F2: 0 | G2: 0 | H2: 0 | I2: 0 | J2: 0 | K2: 0 | L2: 0 | M2: 0 | N2: 0 | O2: 0 | P2: 0 | Q2: 0 | R2: 0 | T2: 0 | U2: 0 | V2: 0 | W2: =V2 -> 0 | X2: 0 | Y2: Website Tidak Dapat Diakses
D3: 2015 | E3: 0 | F3: 0 | G3: 0 | H3: 0 | I3: 0 | J3: 0 | K3: 0 | L3: 0 | M3: 0 | N3: 0 | O3: 0 | P3: 0 | Q3: 0 | R3: 0 | T3: 0 | U3: 0 | V3: 0 | W3: =V3 -> 0 | X3: 0
D4: 2016 | E4: 0 | F4: 0 | G4: 0 | H4: 0 | I4: 0 | J4: 0 | K4: 0 | L4: 0 | M4: 0 | N4: 0 | O4: 0 | P4: 0 | Q4: 0 | R4: 0 | T4: 0 | U4: 0 | V4: 0 | W4: =V4 -> 0 | X4: 0
D5: 2017 | E5: 0 | F5: 0 | G5: 0 | H5: 0 | I5: 0 | J5: 0 | K5: 0 | L5: 0 | M5: 0 | N5: 0 | O5: 0 | P5: 0 | Q5: 0 | R5: 0 | T5: 0 | U5: 0 | V5: 0 | W5: =V5 -> 0 | X5: 0
D6: 2018 | E6: 0 | F6: 0 | G6: 0 | H6: 0 | I6: 0 | J6: 0 | K6: 0 | L6: 0 | M6: 0 | N6: 0 | O6: 0 | P6: 0 | Q6: 0 | R6: 0 | T6: 0 | U6: 0 | V6: 0 | W6: =V6 -> 0 | X6: 0
D7: 2019 | E7: 0 | F7: 0 | G7: 0 | H7: 0 | I7: 0 | J7: 0 | K7: 0 | L7: 0 | M7: 0 | N7: 0 | O7: 0 | P7: 0 | Q7: 0 | R7: 0 | T7: 0 | U7: 0 | V7: 0 | W7: =V7 -> 0 | X7: 0
D8: 2020 | E8: 0 | F8: 0 | G8: 0 | H8: 0 | I8: 0 | J8: 0 | K8: 0 | L8: 0 | M8: 0 | N8: 0 | O8: 0 | P8: 0 | Q8: 0 | R8: 0 | T8: 0 | U8: 0 | V8: 0 | W8: =V8 -> 0 | X8: 0
D9: 2021 | E9: 0 | F9: 0 | G9: 0 | H9: 0 | I9: 0 | J9: 0 | K9: 0 | L9: 0 | M9: 0 | N9: 0 | O9: 0 | P9: 0 | Q9: 0 | R9: 0 | T9: 0 | U9: 0 | V9: 0 | W9: =V9 -> 0 | X9: 0
D10: 2022 | E10: 0 | F10: 0 | G10: 0 | H10: 0 | I10: 0 | J10: 0 | K10: 0 | L10: 0 | M10: 0 | N10: 0 | O10: 0 | P10: 0 | Q10: 0 | R10: 0 | T10: 0 | U10: 0 | V10: 0 | W10: =V10 -> 0 | X10: 0
D11: 2023 | E11: 0 | F11: 0 | G11: 0 | H11: 0 | I11: 0 | J11: 0 | K11: 0 | L11: 0 | M11: 0 | N11: 0 | O11: 0 | P11: 0 | Q11: 0 | R11: 0 | T11: 0 | U11: 0 | V11: 0 | W11: =V11 -> 0 | X11: 0
D12: 2024 | E12: 0 | F12: 0 | G12: 0 | H12: 0 | I12: 0 | J12: 0 | K12: 0 | L12: 0 | M12: 0 | N12: 0 | O12: 0 | P12: 0 | Q12: 0 | R12: 0 | T12: 0 | U12: 0 | V12: 0 | W12: =V12 -> 0 | X12: 0
B13: 2 | C13: PT AIA Financial | D13: 2014 | E13: 0 | F13: 0 | G13: 0 | H13: 0 | I13: 0 | J13: 0 | K13: 0 | L13: =11948691*1000000 -> 11948691000000 | M13: 0 | N13: 0 | O13: 0 | P13: 0 | Q13: 0 | R13: 0 | T13: 0 | U13: 0 | V13: 0 | W13: =V13 -> 0
D14: 2015 | E14: =322334*1000000 -> 322334000000 | F14: =(1650409-423263-273144-2863)*1000000 -> 951139000000 | G14: =31860954*1000000 -> 31860954000000 | H14: =1833519*1000000 -> 1833519000000 | I14: =25291701*1000000 -> 25291701000000 | J14: =5786895*1000000 -> 5786895000000 | K14: =6569253*1000000 -> 6569253000000 | L14: =8985907*1000000 -> 8985907000000 | M14: =1649123*1000000 -> 1649123000000 | N14: =848437*1000000 -> 848437000000 | O14: 0.8 | P14: AIA International Limited | Q14: 2 | R14: 4 | S14: 5 | T14: =S14+R14 -> 9 | U14: 0 | V14: 0 | W14: 0 | X14: 0
D15: 2016 | E15: =383884*1000000 -> 383884000000 | F15: =(1714053-378107-214642-2511)*1000000 -> 1118793000000 | G15: =35767906*1000000 -> 35767906000000 | H15: =2103474*1000000 -> 2103474000000 | I15: =28001542*1000000 -> 28001542000000 | J15: =6850440*1000000 -> 6850440000000 | K15: =7766364*1000000 -> 7766364000000 | L15: =13264521*1000000 -> 13264521000000 | M15: =1034240*1000000 -> 1034240000000 | N15: =1197111*1000000 -> 1197111000000 | O15: 0.8 | P15: AIA International Limited | Q15: 2 | R15: 4 | S15: 5 | T15: =S15+R15 -> 9 | U15: 0 | V15: 0 | W15: 0 | X15: 0
D16: 2017 | E16: =461296*1000000 -> 461296000000 | F16: =(2647963-1137872-205000-15613-2158)*1000000 -> 1287320000000 | G16: =44937292*1000000 -> 44937292000000 | H16: =3116639*1000000 -> 3116639000000 | I16: =34375378*1000000 -> 34375378000000 | J16: =7239986*1000000 -> 7239986000000 | K16: =10561914*1000000 -> 10561914000000 | L16: =15523134*1000000 -> 15523134000000 | M16: =542068*1000000 -> 542068000000 | N16: =1562417*1000000 -> 1562417000000 | O16: 0.95 | P16: AIA International Limited | Q16: 2 | R16: 4 | S16: 5 | T16: =S16+R16 -> 9 | U16: 0 | V16: 0 | W16: 0 | X16: 0
D17: 2018 | E17: =718593*1000000 -> 718593000000 | F17: =(3478638-1737464-222358-7146-1858)*1000000 -> 1509812000000 | G17: =46562563*1000000 -> 46562563000000 | H17: =3329580*1000000 -> 3329580000000 | I17: =35535336*1000000 -> 35535336000000 | J17: =8566661*1000000 -> 8566661000000 | K17: =11027227*1000000 -> 11027227000000 | L17: =12786352*1000000 -> 12786352000000 | M17: =2150147*1000000 -> 2150147000000 | N17: =1065313*1000000 -> 1065313000000 | O17: 0.95 | P17: AIA International Limited | Q17: 2 | R17: 4 | S17: 5 | T17: =S17+R17 -> 9 | U17: 0 | V17: 0 | W17: 0 | X17: 0
D18: 2019 | E18: =1028736*1000000 -> 1028736000000 | F18: =(5436824-3135551-275043-4811-1597)*1000000 -> 2019822000000 | G18: =50043024*1000000 -> 50043024000000 | H18: =3399335*1000000 -> 3399335000000 | I18: =38172435*1000000 -> 38172435000000 | J18: =7904525*1000000 -> 7904525000000 | K18: =11870589*1000000 -> 11870589000000 | L18: =15545577*1000000 -> 15545577000000 | M18: =449893*1000000 -> 449893000000 | N18: =2104310*1000000 -> 2104310000000 | O18: 0.9499 | P18: AIA International Limited | Q18: 2 | R18: 4 | S18: 4 | T18: =S18+R18 -> 8 | U18: 0 | V18: 0 | W18: 0 | X18: 0
D19: 2020 | E19: =1275183*1000000 -> 1275183000000 | F19: =(7128145-4572994-363789-454-1336)*1000000 -> 2189572000000 | G19: =53134780*1000000 -> 53134780000000 | H19: =3640926*1000000 -> 3640926000000 | I19: =41373205*1000000 -> 41373205000000 | J19: =7057134*1000000 -> 7057134000000 | K19: =11761575*1000000 -> 11761575000000 | L19: =15658951*1000000 -> 15658951000000 | M19: =718592*1000000 -> 718592000000 | N19: =(-410562)*1000000 -> -410562000000 | O19: 0.9499 | P19: AIA International Limited | Q19: 2 | R19: 4 | S19: 4 | T19: =S19+R19 -> 8 | U19: 0 | V19: 0 | W19: 0 | X19: 0
D20: 2021 | E20: =1225179*1000000 -> 1225179000000 | F20: =(5404009-2571985-498366-384-1074)*1000000 -> 2332200000000 | G20: =52330016*1000000 -> 52330016000000 | H20: =3465695*1000000 -> 3465695000000 | I20: =40473683*1000000 -> 40473683000000 | J20: =6523045*1000000 -> 6523045000000 | K20: =11856333*1000000 -> 11856333000000 | L20: =15671921*1000000 -> 15671921000000 | M20: =1143810*1000000 -> 1143810000000 | N20: =-586757*1000000 -> -586757000000 | O20: 0.9499 | P20: AIA International Limited | Q20: 1 | R20: 3 | S20: 4 | T20: =S20+R20 -> 7 | U20: 0 | V20: 0 | W20: 0 | X20: 0
D21: 2022 | E21: =1379712*1000000 -> 1379712000000 | F21: =(5171825-2010624-605983-376-905)*1000000 -> 2553937000000 | G21: =44912325*1000000 -> 44912325000000 | H21: =3771309*1000000 -> 3771309000000 | I21: =36682436*1000000 -> 36682436000000 | J21: =5603024*1000000 -> 5603024000000 | K21: =8229889*1000000 -> 8229889000000 | L21: =11948182*1000000 -> 11948182000000 | M21: =2655031*1000000 -> 2655031000000 | N21: =-785208*1000000 -> -785208000000 | O21: 0.9499 | P21: AIA International Limited | Q21: 1 | R21: 3 | S21: 4 | T21: =S21+R21 -> 7 | U21: 0 | V21: 0 | W21: 0 | X21: 0
D22: 2023 | E22: =841975*1000000 -> 841975000000 | F22: =(4935701-1917920-799475-802)*1000000 -> 2217504000000 | G22: =41785302*1000000 -> 41785302000000 | H22: =3324784*1000000 -> 3324784000000 | I22: =33736676*1000000 -> 33736676000000 | J22: =6019271*1000000 -> 6019271000000 | K22: =8048626*1000000 -> 8048626000000 | L22: =12931853*1000000 -> 12931853000000 | M22: =1674911*1000000 -> 1674911000000 | N22: =876769*1000000 -> 876769000000 | O22: 0.9499 | P22: AIA International Limited | Q22: 2 | R22: 4 | S22: 5 | T22: =S22+R22 -> 9 | U22: 0 | V22: 0 | W22: 0 | X22: 0
D23: 2024 | E23: =1063869*1000000 -> 1063869000000 | F23: =(5779370-2783963-760527-699)*1000000 -> 2234181000000 | G23: =39899482*1000000 -> 39899482000000 | H23: =2965577*1000000 -> 2965577000000 | I23: =30987181*1000000 -> 30987181000000 | J23: =7306046*1000000 -> 7306046000000 | K23: =8912301*1000000 -> 8912301000000 | L23: =10095098*1000000 -> 10095098000000 | M23: =1789193*1000000 -> 1789193000000 | N23: =1419919*1000000 -> 1419919000000 | O23: 0.9499 | P23: AIA International Limited | Q23: 1 | R23: 3 | S23: 5 | T23: =S23+R23 -> 8 | U23: 0 | V23: 0 | W23: 0 | X23: 0
B24: 3 | C24: PT Asuransi Allianz Life Indonesia | D24: 2014 | E24: 0 | F24: 0 | G24: 0 | H24: 0 | I24: 0 | J24: 0 | K24: 0 | L24: =12354658*1000000 -> 12354658000000 | M24: 0 | N24: 0 | O24: 0 | P24: 0 | Q24: 0 | R24: 0 | T24: 0 | U24: 0 | W24: =V24 -> 0
D25: 2015 | E25: =459323*1000000 -> 459323000000 | F25: =(459323+26775+202537)*1000000 -> 688635000000 | G25: =27635118*1000000 -> 27635118000000 | H25: =(114268+204780+18994+18963+308951)*1000000 -> 665956000000 | I25: =22909265*1000000 -> 22909265000000 | J25: =3103856*1000000 -> 3103856000000 | K25: =4355995*1000000 -> 4355995000000 | L25: =8593467*1000000 -> 8593467000000 | M25: =903774*1000000 -> 903774000000 | N25: =806099*1000000 -> 806099000000 | O25: 0.9976 | P25: Allianz Asia Pacific & Africa GmbH | Q25: 2 | R25: 3 | S25: 4 | T25: =R25+S25 -> 7 | U25: 0 | V25: 0 | W25: =V25 -> 0 | X25: 0
D26: 2016 | E26: =541939*1000000 -> 541939000000 | F26: =(541939+29637+365907)*1000000 -> 937483000000 | G26: =30294789*1000000 -> 30294789000000 | H26: =(111313+264934+97766+479554)*1000000 -> 953567000000 | I26: =24436046*1000000 -> 24436046000000 | J26: =3996502*1000000 -> 3996502000000 | K26: =5381290*1000000 -> 5381290000000 | L26: =11372680*1000000 -> 11372680000000 | M26: =905890*1000000 -> 905890000000 | N26: =899890*1000000 -> 899890000000 | O26: 0.9976 | P26: Allianz Asia Pacific & Africa GmbH | Q26: 2 | R26: 3 | S26: 4 | T26: =R26+S26 -> 7 | U26: 0 | V26: 0 | W26: =V26 -> 0 | X26: 0
D27: 2017 | E27: =400675*1000000 -> 400675000000 | F27: =(400675+10953+750970)*1000000 -> 1162598000000 | G27: =35751863*1000000 -> 35751863000000 | H27: =(111504+364624+29852+738671)*1000000 -> 1244651000000 | I27: =27527468*1000000 -> 27527468000000 | J27: =4311634*1000000 -> 4311634000000 | K27: =6030989*1000000 -> 6030989000000 | L27: =13302120*1000000 -> 13302120000000 | M27: =329564*1000000 -> 329564000000 | N27: =649699*1000000 -> 649699000000 | O27: 0.9976 | P27: Allianz Asia Pacific & Africa GmbH | Q27: 2 | R27: 4 | S27: 5 | T27: =R27+S27 -> 9 | U27: 0 | V27: 0 | W27: =V27 -> 0 | X27: 0
D28: 2018 | E28: =445074*1000000 -> 445074000000 | F28: =(445074+8503+985111)*1000000 -> 1438688000000 | G28: =35266933*1000000 -> 35266933000000 | H28: =(123243+422315+186769+73+847856)*1000000 -> 1580256000000 | I28: =27304202*1000000 -> 27304202000000 | J28: =4737672*1000000 -> 4737672000000 | K28: =5768100*1000000 -> 5768100000000 | L28: =10531156*1000000 -> 10531156000000 | M28: =899975*1000000 -> 899975000000 | N28: =137111*1000000 -> 137111000000 | O28: 0.9976 | P28: Allianz Asia Pacific & Africa GmbH | Q28: 2 | R28: 3 | S28: 6 | T28: =R28+S28 -> 9 | U28: 0 | V28: 0 | W28: =V28 -> 0 | X28: 0
D29: 2019 | E29: =593701*1000000 -> 593701000000 | F29: =(593701+586967+794491)*1000000 -> 1975159000000 | G29: =38345233*1000000 -> 38345233000000 | H29: =(50269+421228+177272+70491+572518)*1000000 -> 1291778000000 | I29: =29736010*1000000 -> 29736010000000 | J29: =5161928*1000000 -> 5161928000000 | K29: =6511324*1000000 -> 6511324000000 | L29: =15153459*1000000 -> 15153459000000 | M29: =1526889*1000000 -> 1526889000000 | N29: =1493224*1000000 -> 1493224000000 | O29: 0.9976 | P29: Allianz Asia Pacific & Africa GmbH | Q29: 2 | R29: 3 | S29: 6 | T29: =R29+S29 -> 9 | U29: 0 | V29: 0 | W29: =V29 -> 0 | X29: 0
D30: 2020 | E30: =757656*1000000 -> 757656000000 | F30: =(757656+912739+874268)*1000000 -> 2544663000000 | G30: =41166712*1000000 -> 41166712000000 | H30: =(50367+650691+134806+97681+509680)*1000000 -> 1443225000000 | I30: =31830554*1000000 -> 31830554000000 | J30: =5998414*1000000 -> 5998414000000 | K30: =7090980*1000000 -> 7090980000000 | L30: =18812789*1000000 -> 18812789000000 | M30: =1691295*1000000 -> 1691295000000 | N30: =1129656*1000000 -> 1129656000000 | O30: 0.9976 | P30: Allianz Asia Pacific & Africa GmbH | Q30: 2 | R30: 3 | S30: 6 | T30: =R30+S30 -> 9 | U30: 0 | V30: =3+(2*1)+(2*0)+(3*1) -> 8 | W30: =V30 -> 8 | X30: =6+(2*4) -> 14
D31: 2021 | E31: =781493*1000000 -> 781493000000 | F31: =(781493+1075393+994241)*1000000 -> 2851127000000 | G31: =42808931*1000000 -> 42808931000000 | H31: =(87103+679306+83026+1367+689159)*1000000 -> 1539961000000 | I31: =33849131*1000000 -> 33849131000000 | J31: =5949541*1000000 -> 5949541000000 | K31: =6945025*1000000 -> 6945025000000 | L31: =20725660*1000000 -> 20725660000000 | M31: =561475*1000000 -> 561475000000 | N31: =404045*1000000 -> 404045000000 | O31: 0.9976 | P31: Allianz Asia Pacific & Africa GmbH | Q31: 2 | R31: 4 | S31: 5 | T31: =R31+S31 -> 9 | U31: 0 | V31: =4+(2*1)+(2*0)+(3*1) -> 9 | W31: =V31 -> 9 | X31: =5+(2*3) -> 11
D32: 2022 | E32: =917912*1000000 -> 917912000000 | F32: =(917912+1432787+1061310)*1000000 -> 3412009000000 | G32: =41194961*1000000 -> 41194961000000 | H32: =(54342+607177+117687+2986+1539088)*1000000 -> 2321280000000 | I32: =32037270*1000000 -> 32037270000000 | J32: =6757463*1000000 -> 6757463000000 | K32: =7208812*1000000 -> 7208812000000 | L32: =14203983*1000000 -> 14203983000000 | M32: =597200*1000000 -> 597200000000 | N32: =107318*1000000 -> 107318000000 | O32: 0.9976 | P32: Allianz Asia Pacific & Africa GmbH | Q32: 2 | R32: 3 | S32: 4 | T32: =R32+S32 -> 7 | U32: 0 | V32: =3+(2*1)+(3*1) -> 8 | W32: =V32 -> 8 | X32: =4+(2*2) -> 8
D33: 2023 | E33: =1253189*1000000 -> 1253189000000 | F33: =(1253189+1054946+1251808)*1000000 -> 3559943000000 | G33: =40147448*1000000 -> 40147448000000 | H33: =(50113+742554+60377+193361+1535406)*1000000 -> 2581811000000 | I33: =31712785*1000000 -> 31712785000000 | J33: =6154142*1000000 -> 6154142000000 | K33: =6640072*1000000 -> 6640072000000 | L33: =17375945*1000000 -> 17375945000000 | M33: =372376*1000000 -> 372376000000 | N33: =481260*1000000 -> 481260000000 | O33: 0.9976 | P33: Allianz Asia Pacific & Africa GmbH | Q33: 2 | R33: 4 | S33: 4 | T33: =R33+S33 -> 8 | U33: 0 | V33: =3+(2*1)+(3*1) -> 8 | W33: =V33 -> 8 | X33: =4+(2*2)+(2*1) -> 10
D34: 2024 | E34: =1400159*1000000 -> 1400159000000 | F34: =(1400159+565832+619462)*1000000 -> 2585453000000 | G34: =39131978*1000000 -> 39131978000000 | H34: =(74394+717562+214968+7499+1720606)*1000000 -> 2735029000000 | I34: =30372565*1000000 -> 30372565000000 | J34: =6934793*1000000 -> 6934793000000 | K34: =7301939*1000000 -> 7301939000000 | L34: =18185132*1000000 -> 18185132000000 | M34: =1242464*1000000 -> 1242464000000 | N34: =961867*1000000 -> 961867000000 | O34: 0.9976 | P34: Allianz Asia Pacific & Africa GmbH | Q34: 2 | R34: 4 | S34: 3 | T34: =R34+S34 -> 7 | U34: 0 | V34: =3+(2*1)+(3*1) -> 8 | W34: =V34 -> 8 | X34: =2+(2*1)+(2*1) -> 6
B35: 4 | C35: PT Asuransi Allianz Life Syariah Indonesia | D35: 2014 | E35: 0 | F35: 0 | G35: 0 | H35: 0 | I35: 0 | J35: 0 | K35: 0 | L35: 0 | M35: 0 | N35: 0 | O35: 0 | P35: 0 | Q35: 0 | R35: 0 | T35: 0 | U35: 0 | V35: 0 | W35: 0 | X35: 0
D36: 2015 | E36: 0 | F36: 0 | G36: 0 | H36: 0 | I36: 0 | J36: 0 | K36: 0 | L36: 0 | M36: 0 | N36: 0 | O36: 0 | P36: 0 | Q36: 0 | R36: 0 | T36: 0 | U36: 0 | V36: 0 | W36: 0 | X36: 0
D37: 2016 | E37: 0 | F37: 0 | G37: 0 | H37: 0 | I37: 0 | J37: 0 | K37: 0 | L37: 0 | M37: 0 | N37: 0 | O37: 0 | P37: 0 | Q37: 0 | R37: 0 | T37: 0 | U37: 0 | V37: 0 | W37: 0 | X37: 0
D38: 2017 | E38: 0 | F38: 0 | G38: 0 | H38: 0 | I38: 0 | J38: 0 | K38: 0 | L38: 0 | M38: 0 | N38: 0 | O38: 0 | P38: 0 | Q38: 0 | R38: 0 | T38: 0 | U38: 0 | V38: 0 | W38: 0 | X38: 0
D39: 2018 | E39: 0 | F39: 0 | G39: 0 | H39: 0 | I39: 0 | J39: 0 | K39: 0 | L39: 0 | M39: 0 | N39: 0 | O39: 0 | P39: 0 | Q39: 0 | R39: 0 | T39: 0 | U39: 0 | V39: 0 | W39: 0 | X39: 0
D40: 2019 | E40: 0 | F40: 0 | G40: 0 | H40: 0 | I40: 0 | J40: 0 | K40: 0 | L40: 0 | M40: 0 | N40: 0 | O40: 0 | P40: 0 | Q40: 0 | R40: 0 | T40: 0 | U40: 0 | V40: 0 | W40: 0 | X40: 0
...

Sheet Current Ratio
A1: Sub Sektor | B1: No | C1: Nama Perusahaan | D1: Tahun | E1: Aktiva Lancar | F1: Hutang Lancar | G1: Current Ratio
A2: Asuransi Jiwa | B2: 1 | C2: Asuransi Jiwa Bersama Bumiputera 1912 | D2: 2014 | E2: =Data!F2 -> 0 | F2: =Data!H2 -> 0 | G2: =IFERROR(E2/F2,0) -> 0
D3: 2015 | E3: =Data!F3 -> 0 | F3: =Data!H3 -> 0 | G3: =IFERROR(E3/F3,0) -> 0
D4: 2016 | E4: =Data!F4 -> 0 | F4: =Data!H4 -> 0 | G4: =IFERROR(E4/F4,0) -> 0
D5: 2017 | E5: =Data!F5 -> 0 | F5: =Data!H5 -> 0 | G5: =IFERROR(E5/F5,0) -> 0
D6: 2018 | E6: =Data!F6 -> 0 | F6: =Data!H6 -> 0 | G6: =IFERROR(E6/F6,0) -> 0
D7: 2019 | E7: =Data!F7 -> 0 | F7: =Data!H7 -> 0 | G7: =IFERROR(E7/F7,0) -> 0
D8: 2020 | E8: =Data!F8 -> 0 | F8: =Data!H8 -> 0 | G8: =IFERROR(E8/F8,0) -> 0
D9: 2021 | E9: =Data!F9 -> 0 | F9: =Data!H9 -> 0 | G9: =IFERROR(E9/F9,0) -> 0
D10: 2022 | E10: =Data!F10 -> 0 | F10: =Data!H10 -> 0 | G10: =IFERROR(E10/F10,0) -> 0
D11: 2023 | E11: =Data!F11 -> 0 | F11: =Data!H11 -> 0 | G11: =IFERROR(E11/F11,0) -> 0
D12: 2024 | E12: =Data!F12 -> 0 | F12: =Data!H12 -> 0 | G12: =IFERROR(E12/F12,0) -> 0
B13: 2 | C13: PT AIA Financial | D13: 2014 | E13: =Data!F13 -> 0 | F13: =Data!H13 -> 0 | G13: =IFERROR(E13/F13,0) -> 0
D14: 2015 | E14: =Data!F14 -> 951139000000 | F14: =Data!H14 -> 1833519000000 | G14: =IFERROR(E14/F14,0) -> 0.51875056
D15: 2016 | E15: =Data!F15 -> 1118793000000 | F15: =Data!H15 -> 2103474000000 | G15: =IFERROR(E15/F15,0) -> 0.53187869
D16: 2017 | E16: =Data!F16 -> 1287320000000 | F16: =Data!H16 -> 3116639000000 | G16: =IFERROR(E16/F16,0) -> 0.41304752
D17: 2018 | E17: =Data!F17 -> 1509812000000 | F17: =Data!H17 -> 3329580000000 | G17: =IFERROR(E17/F17,0) -> 0.45345419
D18: 2019 | E18: =Data!F18 -> 2019822000000 | F18: =Data!H18 -> 3399335000000 | G18: =IFERROR(E18/F18,0) -> 0.59418151
D19: 2020 | E19: =Data!F19 -> 2189572000000 | F19: =Data!H19 -> 3640926000000 | G19: =IFERROR(E19/F19,0) -> 0.60137778
D20: 2021 | E20: =Data!F20 -> 2332200000000 | F20: =Data!H20 -> 3465695000000 | G20: =IFERROR(E20/F20,0) -> 0.67293862
D21: 2022 | E21: =Data!F21 -> 2553937000000 | F21: =Data!H21 -> 3771309000000 | G21: =IFERROR(E21/F21,0) -> 0.67720174
D22: 2023 | E22: =Data!F22 -> 2217504000000 | F22: =Data!H22 -> 3324784000000 | G22: =IFERROR(E22/F22,0) -> 0.66696182
D23: 2024 | E23: =Data!F23 -> 2234181000000 | F23: =Data!H23 -> 2965577000000 | G23: =IFERROR(E23/F23,0) -> 0.75337143
B24: 3 | C24: PT Asuransi Allianz Life Indonesia | D24: 2014 | E24: =Data!F24 -> 0 | F24: =Data!H24 -> 0 | G24: =IFERROR(E24/F24,0) -> 0
D25: 2015 | E25: =Data!F25 -> 688635000000 | F25: =Data!H25 -> 665956000000 | G25: =IFERROR(E25/F25,0) -> 1.0340548
D26: 2016 | E26: =Data!F26 -> 937483000000 | F26: =Data!H26 -> 953567000000 | G26: =IFERROR(E26/F26,0) -> 0.98313281
D27: 2017 | E27: =Data!F27 -> 1162598000000 | F27: =Data!H27 -> 1244651000000 | G27: =IFERROR(E27/F27,0) -> 0.9340755
D28: 2018 | E28: =Data!F28 -> 1438688000000 | F28: =Data!H28 -> 1580256000000 | G28: =IFERROR(E28/F28,0) -> 0.91041452
D29: 2019 | E29: =Data!F29 -> 1975159000000 | F29: =Data!H29 -> 1291778000000 | G29: =IFERROR(E29/F29,0) -> 1.5290236
D30: 2020 | E30: =Data!F30 -> 2544663000000 | F30: =Data!H30 -> 1443225000000 | G30: =IFERROR(E30/F30,0) -> 1.7631783
D31: 2021 | E31: =Data!F31 -> 2851127000000 | F31: =Data!H31 -> 1539961000000 | G31: =IFERROR(E31/F31,0) -> 1.8514281
D32: 2022 | E32: =Data!F32 -> 3412009000000 | F32: =Data!H32 -> 2321280000000 | G32: =IFERROR(E32/F32,0) -> 1.4698826
D33: 2023 | E33: =Data!F33 -> 3559943000000 | F33: =Data!H33 -> 2581811000000 | G33: =IFERROR(E33/F33,0) -> 1.378855
D34: 2024 | E34: =Data!F34 -> 2585453000000 | F34: =Data!H34 -> 2735029000000 | G34: =IFERROR(E34/F34,0) -> 0.945311
B35: 4 | C35: PT Asuransi Allianz Life Syariah Indonesia | D35: 2014 | E35: =Data!F35 -> 0 | F35: =Data!H35 -> 0 | G35: =IFERROR(E35/F35,0) -> 0
D36: 2015 | E36: =Data!F36 -> 0 | F36: =Data!H36 -> 0 | G36: =IFERROR(E36/F36,0) -> 0
D37: 2016 | E37: =Data!F37 -> 0 | F37: =Data!H37 -> 0 | G37: =IFERROR(E37/F37,0) -> 0
D38: 2017 | E38: =Data!F38 -> 0 | F38: =Data!H38 -> 0 | G38: =IFERROR(E38/F38,0) -> 0
D39: 2018 | E39: =Data!F39 -> 0 | F39: =Data!H39 -> 0 | G39: =IFERROR(E39/F39,0) -> 0
D40: 2019 | E40: =Data!F40 -> 0 | F40: =Data!H40 -> 0 | G40: =IFERROR(E40/F40,0) -> 0
...

Sheet Cash Ratio
A1: Sub Sektor | B1: No | C1: Nama Perusahaan | D1: Tahun | E1: Kas | F1: Hutang Lancar | G1: Cash Ratio
A2: Asuransi Jiwa | B2: 1 | C2: Asuransi Jiwa Bersama Bumiputera 1912 | D2: 2014 | E2: =Data!E2 -> 0 | F2: =Data!H2 -> 0 | G2: =IFERROR(E2/F2,0) -> 0
D3: 2015 | E3: =Data!E3 -> 0 | F3: =Data!H3 -> 0 | G3: =IFERROR(E3/F3,0) -> 0
D4: 2016 | E4: =Data!E4 -> 0 | F4: =Data!H4 -> 0 | G4: =IFERROR(E4/F4,0) -> 0
D5: 2017 | E5: =Data!E5 -> 0 | F5: =Data!H5 -> 0 | G5: =IFERROR(E5/F5,0) -> 0
D6: 2018 | E6: =Data!E6 -> 0 | F6: =Data!H6 -> 0 | G6: =IFERROR(E6/F6,0) -> 0
D7: 2019 | E7: =Data!E7 -> 0 | F7: =Data!H7 -> 0 | G7: =IFERROR(E7/F7,0) -> 0
D8: 2020 | E8: =Data!E8 -> 0 | F8: =Data!H8 -> 0 | G8: =IFERROR(E8/F8,0) -> 0
D9: 2021 | E9: =Data!E9 -> 0 | F9: =Data!H9 -> 0 | G9: =IFERROR(E9/F9,0) -> 0
D10: 2022 | E10: =Data!E10 -> 0 | F10: =Data!H10 -> 0 | G10: =IFERROR(E10/F10,0) -> 0
D11: 2023 | E11: =Data!E11 -> 0 | F11: =Data!H11 -> 0 | G11: =IFERROR(E11/F11,0) -> 0
D12: 2024 | E12: =Data!E12 -> 0 | F12: =Data!H12 -> 0 | G12: =IFERROR(E12/F12,0) -> 0
B13: 2 | C13: PT AIA Financial | D13: 2014 | E13: =Data!E13 -> 0 | F13: =Data!H13 -> 0 | G13: =IFERROR(E13/F13,0) -> 0
D14: 2015 | E14: =Data!E14 -> 322334000000 | F14: =Data!H14 -> 1833519000000 | G14: =IFERROR(E14/F14,0) -> 0.17580074
D15: 2016 | E15: =Data!E15 -> 383884000000 | F15: =Data!H15 -> 2103474000000 | G15: =IFERROR(E15/F15,0) -> 0.1825
D16: 2017 | E16: =Data!E16 -> 461296000000 | F16: =Data!H16 -> 3116639000000 | G16: =IFERROR(E16/F16,0) -> 0.14801073
D17: 2018 | E17: =Data!E17 -> 718593000000 | F17: =Data!H17 -> 3329580000000 | G17: =IFERROR(E17/F17,0) -> 0.21582091
D18: 2019 | E18: =Data!E18 -> 1028736000000 | F18: =Data!H18 -> 3399335000000 | G18: =IFERROR(E18/F18,0) -> 0.3026286
D19: 2020 | E19: =Data!E19 -> 1275183000000 | F19: =Data!H19 -> 3640926000000 | G19: =IFERROR(E19/F19,0) -> 0.3502359
D20: 2021 | E20: =Data!E20 -> 1225179000000 | F20: =Data!H20 -> 3465695000000 | G20: =IFERROR(E20/F20,0) -> 0.35351611
D21: 2022 | E21: =Data!E21 -> 1379712000000 | F21: =Data!H21 -> 3771309000000 | G21: =IFERROR(E21/F21,0) -> 0.36584433
D22: 2023 | E22: =Data!E22 -> 841975000000 | F22: =Data!H22 -> 3324784000000 | G22: =IFERROR(E22/F22,0) -> 0.25324202
D23: 2024 | E23: =Data!E23 -> 1063869000000 | F23: =Data!H23 -> 2965577000000 | G23: =IFERROR(E23/F23,0) -> 0.35873929
B24: 3 | C24: PT Asuransi Allianz Life Indonesia | D24: 2014 | E24: =Data!E24 -> 0 | F24: =Data!H24 -> 0 | G24: =IFERROR(E24/F24,0) -> 0
D25: 2015 | E25: =Data!E25 -> 459323000000 | F25: =Data!H25 -> 665956000000 | G25: =IFERROR(E25/F25,0) -> 0.68971974
D26: 2016 | E26: =Data!E26 -> 541939000000 | F26: =Data!H26 -> 953567000000 | G26: =IFERROR(E26/F26,0) -> 0.56832818
D27: 2017 | E27: =Data!E27 -> 400675000000 | F27: =Data!H27 -> 1244651000000 | G27: =IFERROR(E27/F27,0) -> 0.32191755
D28: 2018 | E28: =Data!E28 -> 445074000000 | F28: =Data!H28 -> 1580256000000 | G28: =IFERROR(E28/F28,0) -> 0.28164677
D29: 2019 | E29: =Data!E29 -> 593701000000 | F29: =Data!H29 -> 1291778000000 | G29: =IFERROR(E29/F29,0) -> 0.45959987
D30: 2020 | E30: =Data!E30 -> 757656000000 | F30: =Data!H30 -> 1443225000000 | G30: =IFERROR(E30/F30,0) -> 0.52497428
D31: 2021 | E31: =Data!E31 -> 781493000000 | F31: =Data!H31 -> 1539961000000 | G31: =IFERROR(E31/F31,0) -> 0.50747584
D32: 2022 | E32: =Data!E32 -> 917912000000 | F32: =Data!H32 -> 2321280000000 | G32: =IFERROR(E32/F32,0) -> 0.39543355
D33: 2023 | E33: =Data!E33 -> 1253189000000 | F33: =Data!H33 -> 2581811000000 | G33: =IFERROR(E33/F33,0) -> 0.48539146
D34: 2024 | E34: =Data!E34 -> 1400159000000 | F34: =Data!H34 -> 2735029000000 | G34: =IFERROR(E34/F34,0) -> 0.51193571
B35: 4 | C35: PT Asuransi Allianz Life Syariah Indonesia | D35: 2014 | E35: =Data!E35 -> 0 | F35: =Data!H35 -> 0 | G35: =IFERROR(E35/F35,0) -> 0
D36: 2015 | E36: =Data!E36 -> 0 | F36: =Data!H36 -> 0 | G36: =IFERROR(E36/F36,0) -> 0
D37: 2016 | E37: =Data!E37 -> 0 | F37: =Data!H37 -> 0 | G37: =IFERROR(E37/F37,0) -> 0
D38: 2017 | E38: =Data!E38 -> 0 | F38: =Data!H38 -> 0 | G38: =IFERROR(E38/F38,0) -> 0
D39: 2018 | E39: =Data!E39 -> 0 | F39: =Data!H39 -> 0 | G39: =IFERROR(E39/F39,0) -> 0
D40: 2019 | E40: =Data!E40 -> 0 | F40: =Data!H40 -> 0 | G40: =IFERROR(E40/F40,0) -> 0
...

Sheet DAR
A1: Sub Sektor | B1: No | C1: Nama Perusahaan | D1: Tahun | E1: Total Hutang | F1: Total Aset | G1: Debt to Asset Ratio
A2: Asuransi Jiwa | B2: 1 | C2: Asuransi Jiwa Bersama Bumiputera 1912 | D2: 2014 | E2: =Data!I2 -> 0 | F2: =Data!G2 -> 0 | G2: =IFERROR(E2/F2,0) -> 0
D3: 2015 | E3: =Data!I3 -> 0 | F3: =Data!G3 -> 0 | G3: =IFERROR(E3/F3,0) -> 0
D4: 2016 | E4: =Data!I4 -> 0 | F4: =Data!G4 -> 0 | G4: =IFERROR(E4/F4,0) -> 0
D5: 2017 | E5: =Data!I5 -> 0 | F5: =Data!G5 -> 0 | G5: =IFERROR(E5/F5,0) -> 0
D6: 2018 | E6: =Data!I6 -> 0 | F6: =Data!G6 -> 0 | G6: =IFERROR(E6/F6,0) -> 0
D7: 2019 | E7: =Data!I7 -> 0 | F7: =Data!G7 -> 0 | G7: =IFERROR(E7/F7,0) -> 0
D8: 2020 | E8: =Data!I8 -> 0 | F8: =Data!G8 -> 0 | G8: =IFERROR(E8/F8,0) -> 0
D9: 2021 | E9: =Data!I9 -> 0 | F9: =Data!G9 -> 0 | G9: =IFERROR(E9/F9,0) -> 0
D10: 2022 | E10: =Data!I10 -> 0 | F10: =Data!G10 -> 0 | G10: =IFERROR(E10/F10,0) -> 0
D11: 2023 | E11: =Data!I11 -> 0 | F11: =Data!G11 -> 0 | G11: =IFERROR(E11/F11,0) -> 0
D12: 2024 | E12: =Data!I12 -> 0 | F12: =Data!G12 -> 0 | G12: =IFERROR(E12/F12,0) -> 0
B13: 2 | C13: PT AIA Financial | D13: 2014 | E13: =Data!I13 -> 0 | F13: =Data!G13 -> 0 | G13: =IFERROR(E13/F13,0) -> 0
D14: 2015 | E14: =Data!I14 -> 25291701000000 | F14: =Data!G14 -> 31860954000000 | G14: =IFERROR(E14/F14,0) -> 0.79381493
D15: 2016 | E15: =Data!I15 -> 28001542000000 | F15: =Data!G15 -> 35767906000000 | G15: =IFERROR(E15/F15,0) -> 0.7828678
D16: 2017 | E16: =Data!I16 -> 34375378000000 | F16: =Data!G16 -> 44937292000000 | G16: =IFERROR(E16/F16,0) -> 0.76496327
D17: 2018 | E17: =Data!I17 -> 35535336000000 | F17: =Data!G17 -> 46562563000000 | G17: =IFERROR(E17/F17,0) -> 0.76317397
D18: 2019 | E18: =Data!I18 -> 38172435000000 | F18: =Data!G18 -> 50043024000000 | G18: =IFERROR(E18/F18,0) -> 0.76279233
D19: 2020 | E19: =Data!I19 -> 41373205000000 | F19: =Data!G19 -> 53134780000000 | G19: =IFERROR(E19/F19,0) -> 0.7786464
D20: 2021 | E20: =Data!I20 -> 40473683000000 | F20: =Data!G20 -> 52330016000000 | G20: =IFERROR(E20/F20,0) -> 0.7734315
D21: 2022 | E21: =Data!I21 -> 36682436000000 | F21: =Data!G21 -> 44912325000000 | G21: =IFERROR(E21/F21,0) -> 0.81675656
D22: 2023 | E22: =Data!I22 -> 33736676000000 | F22: =Data!G22 -> 41785302000000 | G22: =IFERROR(E22/F22,0) -> 0.80738141
D23: 2024 | E23: =Data!I23 -> 30987181000000 | F23: =Data!G23 -> 39899482000000 | G23: =IFERROR(E23/F23,0) -> 0.77663116
B24: 3 | C24: PT Asuransi Allianz Life Indonesia | D24: 2014 | E24: =Data!I24 -> 0 | F24: =Data!G24 -> 0 | G24: =IFERROR(E24/F24,0) -> 0
D25: 2015 | E25: =Data!I25 -> 22909265000000 | F25: =Data!G25 -> 27635118000000 | G25: =IFERROR(E25/F25,0) -> 0.82899103
D26: 2016 | E26: =Data!I26 -> 24436046000000 | F26: =Data!G26 -> 30294789000000 | G26: =IFERROR(E26/F26,0) -> 0.80660889
D27: 2017 | E27: =Data!I27 -> 27527468000000 | F27: =Data!G27 -> 35751863000000 | G27: =IFERROR(E27/F27,0) -> 0.76995898
D28: 2018 | E28: =Data!I28 -> 27304202000000 | F28: =Data!G28 -> 35266933000000 | G28: =IFERROR(E28/F28,0) -> 0.77421538
D29: 2019 | E29: =Data!I29 -> 29736010000000 | F29: =Data!G29 -> 38345233000000 | G29: =IFERROR(E29/F29,0) -> 0.77548127
D30: 2020 | E30: =Data!I30 -> 31830554000000 | F30: =Data!G30 -> 41166712000000 | G30: =IFERROR(E30/F30,0) -> 0.77321099
D31: 2021 | E31: =Data!I31 -> 33849131000000 | F31: =Data!G31 -> 42808931000000 | G31: =IFERROR(E31/F31,0) -> 0.79070255
D32: 2022 | E32: =Data!I32 -> 32037270000000 | F32: =Data!G32 -> 41194961000000 | G32: =IFERROR(E32/F32,0) -> 0.77769876
D33: 2023 | E33: =Data!I33 -> 31712785000000 | F33: =Data!G33 -> 40147448000000 | G33: =IFERROR(E33/F33,0) -> 0.78990787
D34: 2024 | E34: =Data!I34 -> 30372565000000 | F34: =Data!G34 -> 39131978000000 | G34: =IFERROR(E34/F34,0) -> 0.77615716
B35: 4 | C35: PT Asuransi Allianz Life Syariah Indonesia | D35: 2014 | E35: =Data!I35 -> 0 | F35: =Data!G35 -> 0 | G35: =IFERROR(E35/F35,0) -> 0
D36: 2015 | E36: =Data!I36 -> 0 | F36: =Data!G36 -> 0 | G36: =IFERROR(E36/F36,0) -> 0
D37: 2016 | E37: =Data!I37 -> 0 | F37: =Data!G37 -> 0 | G37: =IFERROR(E37/F37,0) -> 0
D38: 2017 | E38: =Data!I38 -> 0 | F38: =Data!G38 -> 0 | G38: =IFERROR(E38/F38,0) -> 0
D39: 2018 | E39: =Data!I39 -> 0 | F39: =Data!G39 -> 0 | G39: =IFERROR(E39/F39,0) -> 0
D40: 2019 | E40: =Data!I40 -> 0 | F40: =Data!G40 -> 0 | G40: =IFERROR(E40/F40,0) -> 0
...

Sheet DER
A1: Sub Sektor | B1: No | C1: Nama Perusahaan | D1: Tahun | E1: Total Hutang | F1: Total Ekuitas | G1: Debt to Equity Ratio
A2: Asuransi Jiwa | B2: 1 | C2: Asuransi Jiwa Bersama Bumiputera 1912 | D2: 2014 | E2: =Data!I2 -> 0 | F2: =Data!K2 -> 0 | G2: =IFERROR(E2/F2,0) -> 0
D3: 2015 | E3: =Data!I3 -> 0 | F3: =Data!K3 -> 0 | G3: =IFERROR(E3/F3,0) -> 0
D4: 2016 | E4: =Data!I4 -> 0 | F4: =Data!K4 -> 0 | G4: =IFERROR(E4/F4,0) -> 0
D5: 2017 | E5: =Data!I5 -> 0 | F5: =Data!K5 -> 0 | G5: =IFERROR(E5/F5,0) -> 0
D6: 2018 | E6: =Data!I6 -> 0 | F6: =Data!K6 -> 0 | G6: =IFERROR(E6/F6,0) -> 0
D7: 2019 | E7: =Data!I7 -> 0 | F7: =Data!K7 -> 0 | G7: =IFERROR(E7/F7,0) -> 0
D8: 2020 | E8: =Data!I8 -> 0 | F8: =Data!K8 -> 0 | G8: =IFERROR(E8/F8,0) -> 0
D9: 2021 | E9: =Data!I9 -> 0 | F9: =Data!K9 -> 0 | G9: =IFERROR(E9/F9,0) -> 0
D10: 2022 | E10: =Data!I10 -> 0 | F10: =Data!K10 -> 0 | G10: =IFERROR(E10/F10,0) -> 0
D11: 2023 | E11: =Data!I11 -> 0 | F11: =Data!K11 -> 0 | G11: =IFERROR(E11/F11,0) -> 0
D12: 2024 | E12: =Data!I12 -> 0 | F12: =Data!K12 -> 0 | G12: =IFERROR(E12/F12,0) -> 0
B13: 2 | C13: PT AIA Financial | D13: 2014 | E13: =Data!I13 -> 0 | F13: =Data!K13 -> 0 | G13: =IFERROR(E13/F13,0) -> 0
D14: 2015 | E14: =Data!I14 -> 25291701000000 | F14: =Data!K14 -> 6569253000000 | G14: =IFERROR(E14/F14,0) -> 3.8500117
D15: 2016 | E15: =Data!I15 -> 28001542000000 | F15: =Data!K15 -> 7766364000000 | G15: =IFERROR(E15/F15,0) -> 3.6054893
D16: 2017 | E16: =Data!I16 -> 34375378000000 | F16: =Data!K16 -> 10561914000000 | G16: =IFERROR(E16/F16,0) -> 3.2546542
D17: 2018 | E17: =Data!I17 -> 35535336000000 | F17: =Data!K17 -> 11027227000000 | G17: =IFERROR(E17/F17,0) -> 3.2225088
D18: 2019 | E18: =Data!I18 -> 38172435000000 | F18: =Data!K18 -> 11870589000000 | G18: =IFERROR(E18/F18,0) -> 3.2157153
D19: 2020 | E19: =Data!I19 -> 41373205000000 | F19: =Data!K19 -> 11761575000000 | G19: =IFERROR(E19/F19,0) -> 3.5176586
D20: 2021 | E20: =Data!I20 -> 40473683000000 | F20: =Data!K20 -> 11856333000000 | G20: =IFERROR(E20/F20,0) -> 3.4136763
D21: 2022 | E21: =Data!I21 -> 36682436000000 | F21: =Data!K21 -> 8229889000000 | G21: =IFERROR(E21/F21,0) -> 4.4572212
D22: 2023 | E22: =Data!I22 -> 33736676000000 | F22: =Data!K22 -> 8048626000000 | G22: =IFERROR(E22/F22,0) -> 4.1916069
D23: 2024 | E23: =Data!I23 -> 30987181000000 | F23: =Data!K23 -> 8912301000000 | G23: =IFERROR(E23/F23,0) -> 3.4769002
B24: 3 | C24: PT Asuransi Allianz Life Indonesia | D24: 2014 | E24: =Data!I24 -> 0 | F24: =Data!K24 -> 0 | G24: =IFERROR(E24/F24,0) -> 0
D25: 2015 | E25: =Data!I25 -> 22909265000000 | F25: =Data!K25 -> 4355995000000 | G25: =IFERROR(E25/F25,0) -> 5.2592496
D26: 2016 | E26: =Data!I26 -> 24436046000000 | F26: =Data!K26 -> 5381290000000 | G26: =IFERROR(E26/F26,0) -> 4.5409272
D27: 2017 | E27: =Data!I27 -> 27527468000000 | F27: =Data!K27 -> 6030989000000 | G27: =IFERROR(E27/F27,0) -> 4.5643373
D28: 2018 | E28: =Data!I28 -> 27304202000000 | F28: =Data!K28 -> 5768100000000 | G28: =IFERROR(E28/F28,0) -> 4.7336561
D29: 2019 | E29: =Data!I29 -> 29736010000000 | F29: =Data!K29 -> 6511324000000 | G29: =IFERROR(E29/F29,0) -> 4.5668147
D30: 2020 | E30: =Data!I30 -> 31830554000000 | F30: =Data!K30 -> 7090980000000 | G30: =IFERROR(E30/F30,0) -> 4.4888794
D31: 2021 | E31: =Data!I31 -> 33849131000000 | F31: =Data!K31 -> 6945025000000 | G31: =IFERROR(E31/F31,0) -> 4.8738674
D32: 2022 | E32: =Data!I32 -> 32037270000000 | F32: =Data!K32 -> 7208812000000 | G32: =IFERROR(E32/F32,0) -> 4.4441816
D33: 2023 | E33: =Data!I33 -> 31712785000000 | F33: =Data!K33 -> 6640072000000 | G33: =IFERROR(E33/F33,0) -> 4.77597
D34: 2024 | E34: =Data!I34 -> 30372565000000 | F34: =Data!K34 -> 7301939000000 | G34: =IFERROR(E34/F34,0) -> 4.1595205
B35: 4 | C35: PT Asuransi Allianz Life Syariah Indonesia | D35: 2014 | E35: =Data!I35 -> 0 | F35: =Data!K35 -> 0 | G35: =IFERROR(E35/F35,0) -> 0
D36: 2015 | E36: =Data!I36 -> 0 | F36: =Data!K36 -> 0 | G36: =IFERROR(E36/F36,0) -> 0
D37: 2016 | E37: =Data!I37 -> 0 | F37: =Data!K37 -> 0 | G37: =IFERROR(E37/F37,0) -> 0
D38: 2017 | E38: =Data!I38 -> 0 | F38: =Data!K38 -> 0 | G38: =IFERROR(E38/F38,0) -> 0
D39: 2018 | E39: =Data!I39 -> 0 | F39: =Data!K39 -> 0 | G39: =IFERROR(E39/F39,0) -> 0
D40: 2019 | E40: =Data!I40 -> 0 | F40: =Data!K40 -> 0 | G40: =IFERROR(E40/F40,0) -> 0
...

Sheet NPM
A1: Sub Sektor | B1: No | C1: Nama Perusahaan | D1: Tahun | E1: Laba Bersih | F1: Total Pendapatan | G1: Net Profit Margin
A2: Asuransi Jiwa | B2: 1 | C2: Asuransi Jiwa Bersama Bumiputera 1912 | D2: 2014 | E2: =Data!N2 -> 0 | F2: =Data!L2 -> 0 | G2: =IFERROR(E2/F2,0) -> 0
D3: 2015 | E3: =Data!N3 -> 0 | F3: =Data!L3 -> 0 | G3: =IFERROR(E3/F3,0) -> 0
D4: 2016 | E4: =Data!N4 -> 0 | F4: =Data!L4 -> 0 | G4: =IFERROR(E4/F4,0) -> 0
D5: 2017 | E5: =Data!N5 -> 0 | F5: =Data!L5 -> 0 | G5: =IFERROR(E5/F5,0) -> 0
D6: 2018 | E6: =Data!N6 -> 0 | F6: =Data!L6 -> 0 | G6: =IFERROR(E6/F6,0) -> 0
D7: 2019 | E7: =Data!N7 -> 0 | F7: =Data!L7 -> 0 | G7: =IFERROR(E7/F7,0) -> 0
D8: 2020 | E8: =Data!N8 -> 0 | F8: =Data!L8 -> 0 | G8: =IFERROR(E8/F8,0) -> 0
D9: 2021 | E9: =Data!N9 -> 0 | F9: =Data!L9 -> 0 | G9: =IFERROR(E9/F9,0) -> 0
D10: 2022 | E10: =Data!N10 -> 0 | F10: =Data!L10 -> 0 | G10: =IFERROR(E10/F10,0) -> 0
D11: 2023 | E11: =Data!N11 -> 0 | F11: =Data!L11 -> 0 | G11: =IFERROR(E11/F11,0) -> 0
D12: 2024 | E12: =Data!N12 -> 0 | F12: =Data!L12 -> 0 | G12: =IFERROR(E12/F12,0) -> 0
B13: 2 | C13: PT AIA Financial | D13: 2014 | E13: =Data!N13 -> 0 | F13: =Data!L13 -> 11948691000000 | G13: =IFERROR(E13/F13,0) -> 0
D14: 2015 | E14: =Data!N14 -> 848437000000 | F14: =Data!L14 -> 8985907000000 | G14: =IFERROR(E14/F14,0) -> 0.094418627
D15: 2016 | E15: =Data!N15 -> 1197111000000 | F15: =Data!L15 -> 13264521000000 | G15: =IFERROR(E15/F15,0) -> 0.090249094
D16: 2017 | E16: =Data!N16 -> 1562417000000 | F16: =Data!L16 -> 15523134000000 | G16: =IFERROR(E16/F16,0) -> 0.10065087
D17: 2018 | E17: =Data!N17 -> 1065313000000 | F17: =Data!L17 -> 12786352000000 | G17: =IFERROR(E17/F17,0) -> 0.083316414
D18: 2019 | E18: =Data!N18 -> 2104310000000 | F18: =Data!L18 -> 15545577000000 | G18: =IFERROR(E18/F18,0) -> 0.1353639
D19: 2020 | E19: =Data!N19 -> -410562000000 | F19: =Data!L19 -> 15658951000000 | G19: =IFERROR(E19/F19,0) -> -0.026218998
D20: 2021 | E20: =Data!N20 -> -586757000000 | F20: =Data!L20 -> 15671921000000 | G20: =IFERROR(E20/F20,0) -> -0.037440018
D21: 2022 | E21: =Data!N21 -> -785208000000 | F21: =Data!L21 -> 11948182000000 | G21: =IFERROR(E21/F21,0) -> -0.06571778
D22: 2023 | E22: =Data!N22 -> 876769000000 | F22: =Data!L22 -> 12931853000000 | G22: =IFERROR(E22/F22,0) -> 0.067799178
D23: 2024 | E23: =Data!N23 -> 1419919000000 | F23: =Data!L23 -> 10095098000000 | G23: =IFERROR(E23/F23,0) -> 0.14065431
B24: 3 | C24: PT Asuransi Allianz Life Indonesia | D24: 2014 | E24: =Data!N24 -> 0 | F24: =Data!L24 -> 12354658000000 | G24: =IFERROR(E24/F24,0) -> 0
D25: 2015 | E25: =Data!N25 -> 806099000000 | F25: =Data!L25 -> 8593467000000 | G25: =IFERROR(E25/F25,0) -> 0.0938037
D26: 2016 | E26: =Data!N26 -> 899890000000 | F26: =Data!L26 -> 11372680000000 | G26: =IFERROR(E26/F26,0) -> 0.079127347
D27: 2017 | E27: =Data!N27 -> 649699000000 | F27: =Data!L27 -> 13302120000000 | G27: =IFERROR(E27/F27,0) -> 0.048841764
D28: 2018 | E28: =Data!N28 -> 137111000000 | F28: =Data!L28 -> 10531156000000 | G28: =IFERROR(E28/F28,0) -> 0.013019558
D29: 2019 | E29: =Data!N29 -> 1493224000000 | F29: =Data!L29 -> 15153459000000 | G29: =IFERROR(E29/F29,0) -> 0.098540142
D30: 2020 | E30: =Data!N30 -> 1129656000000 | F30: =Data!L30 -> 18812789000000 | G30: =IFERROR(E30/F30,0) -> 0.060047237
D31: 2021 | E31: =Data!N31 -> 404045000000 | F31: =Data!L31 -> 20725660000000 | G31: =IFERROR(E31/F31,0) -> 0.019494916
D32: 2022 | E32: =Data!N32 -> 107318000000 | F32: =Data!L32 -> 14203983000000 | G32: =IFERROR(E32/F32,0) -> 0.0075554864
D33: 2023 | E33: =Data!N33 -> 481260000000 | F33: =Data!L33 -> 17375945000000 | G33: =IFERROR(E33/F33,0) -> 0.027696911
D34: 2024 | E34: =Data!N34 -> 961867000000 | F34: =Data!L34 -> 18185132000000 | G34: =IFERROR(E34/F34,0) -> 0.052893045
B35: 4 | C35: PT Asuransi Allianz Life Syariah Indonesia | D35: 2014 | E35: =Data!N35 -> 0 | F35: =Data!L35 -> 0 | G35: =IFERROR(E35/F35,0) -> 0
D36: 2015 | E36: =Data!N36 -> 0 | F36: =Data!L36 -> 0 | G36: =IFERROR(E36/F36,0) -> 0
D37: 2016 | E37: =Data!N37 -> 0 | F37: =Data!L37 -> 0 | G37: =IFERROR(E37/F37,0) -> 0
D38: 2017 | E38: =Data!N38 -> 0 | F38: =Data!L38 -> 0 | G38: =IFERROR(E38/F38,0) -> 0
D39: 2018 | E39: =Data!N39 -> 0 | F39: =Data!L39 -> 0 | G39: =IFERROR(E39/F39,0) -> 0
D40: 2019 | E40: =Data!N40 -> 0 | F40: =Data!L40 -> 0 | G40: =IFERROR(E40/F40,0) -> 0
...

Sheet ROA
A1: Sub Sektor | B1: No | C1: Nama Perusahaan | D1: Tahun | E1: Laba Bersih | F1: Total Aset | G1: Retun on Asset
A2: Asuransi Jiwa | B2: 1 | C2: Asuransi Jiwa Bersama Bumiputera 1912 | D2: 2014 | E2: =Data!N2 -> 0 | F2: =Data!G2 -> 0 | G2: =IFERROR(E2/F2,0) -> 0
D3: 2015 | E3: =Data!N3 -> 0 | F3: =Data!G3 -> 0 | G3: =IFERROR(E3/F3,0) -> 0
D4: 2016 | E4: =Data!N4 -> 0 | F4: =Data!G4 -> 0 | G4: =IFERROR(E4/F4,0) -> 0
D5: 2017 | E5: =Data!N5 -> 0 | F5: =Data!G5 -> 0 | G5: =IFERROR(E5/F5,0) -> 0
D6: 2018 | E6: =Data!N6 -> 0 | F6: =Data!G6 -> 0 | G6: =IFERROR(E6/F6,0) -> 0
D7: 2019 | E7: =Data!N7 -> 0 | F7: =Data!G7 -> 0 | G7: =IFERROR(E7/F7,0) -> 0
D8: 2020 | E8: =Data!N8 -> 0 | F8: =Data!G8 -> 0 | G8: =IFERROR(E8/F8,0) -> 0
D9: 2021 | E9: =Data!N9 -> 0 | F9: =Data!G9 -> 0 | G9: =IFERROR(E9/F9,0) -> 0
D10: 2022 | E10: =Data!N10 -> 0 | F10: =Data!G10 -> 0 | G10: =IFERROR(E10/F10,0) -> 0
D11: 2023 | E11: =Data!N11 -> 0 | F11: =Data!G11 -> 0 | G11: =IFERROR(E11/F11,0) -> 0
D12: 2024 | E12: =Data!N12 -> 0 | F12: =Data!G12 -> 0 | G12: =IFERROR(E12/F12,0) -> 0
B13: 2 | C13: PT AIA Financial | D13: 2014 | E13: =Data!N13 -> 0 | F13: =Data!G13 -> 0 | G13: =IFERROR(E13/F13,0) -> 0
D14: 2015 | E14: =Data!N14 -> 848437000000 | F14: =Data!G14 -> 31860954000000 | G14: =IFERROR(E14/F14,0) -> 0.026629366
D15: 2016 | E15: =Data!N15 -> 1197111000000 | F15: =Data!G15 -> 35767906000000 | G15: =IFERROR(E15/F15,0) -> 0.033468859
D16: 2017 | E16: =Data!N16 -> 1562417000000 | F16: =Data!G16 -> 44937292000000 | G16: =IFERROR(E16/F16,0) -> 0.034768829
D17: 2018 | E17: =Data!N17 -> 1065313000000 | F17: =Data!G17 -> 46562563000000 | G17: =IFERROR(E17/F17,0) -> 0.022879174
D18: 2019 | E18: =Data!N18 -> 2104310000000 | F18: =Data!G18 -> 50043024000000 | G18: =IFERROR(E18/F18,0) -> 0.042050017
D19: 2020 | E19: =Data!N19 -> -410562000000 | F19: =Data!G19 -> 53134780000000 | G19: =IFERROR(E19/F19,0) -> -0.0077268034
D20: 2021 | E20: =Data!N20 -> -586757000000 | F20: =Data!G20 -> 52330016000000 | G20: =IFERROR(E20/F20,0) -> -0.011212628
D21: 2022 | E21: =Data!N21 -> -785208000000 | F21: =Data!G21 -> 44912325000000 | G21: =IFERROR(E21/F21,0) -> -0.01748313
D22: 2023 | E22: =Data!N22 -> 876769000000 | F22: =Data!G22 -> 41785302000000 | G22: =IFERROR(E22/F22,0) -> 0.020982713
D23: 2024 | E23: =Data!N23 -> 1419919000000 | F23: =Data!G23 -> 39899482000000 | G23: =IFERROR(E23/F23,0) -> 0.035587404
B24: 3 | C24: PT Asuransi Allianz Life Indonesia | D24: 2014 | E24: =Data!N24 -> 0 | F24: =Data!G24 -> 0 | G24: =IFERROR(E24/F24,0) -> 0
D25: 2015 | E25: =Data!N25 -> 806099000000 | F25: =Data!G25 -> 27635118000000 | G25: =IFERROR(E25/F25,0) -> 0.029169371
D26: 2016 | E26: =Data!N26 -> 899890000000 | F26: =Data!G26 -> 30294789000000 | G26: =IFERROR(E26/F26,0) -> 0.029704449
D27: 2017 | E27: =Data!N27 -> 649699000000 | F27: =Data!G27 -> 35751863000000 | G27: =IFERROR(E27/F27,0) -> 0.018172452
D28: 2018 | E28: =Data!N28 -> 137111000000 | F28: =Data!G28 -> 35266933000000 | G28: =IFERROR(E28/F28,0) -> 0.0038878062
D29: 2019 | E29: =Data!N29 -> 1493224000000 | F29: =Data!G29 -> 38345233000000 | G29: =IFERROR(E29/F29,0) -> 0.038941581
D30: 2020 | E30: =Data!N30 -> 1129656000000 | F30: =Data!G30 -> 41166712000000 | G30: =IFERROR(E30/F30,0) -> 0.027441006
D31: 2021 | E31: =Data!N31 -> 404045000000 | F31: =Data!G31 -> 42808931000000 | G31: =IFERROR(E31/F31,0) -> 0.0094383343
D32: 2022 | E32: =Data!N32 -> 107318000000 | F32: =Data!G32 -> 41194961000000 | G32: =IFERROR(E32/F32,0) -> 0.0026051244
D33: 2023 | E33: =Data!N33 -> 481260000000 | F33: =Data!G33 -> 40147448000000 | G33: =IFERROR(E33/F33,0) -> 0.011987312
D34: 2024 | E34: =Data!N34 -> 961867000000 | F34: =Data!G34 -> 39131978000000 | G34: =IFERROR(E34/F34,0) -> 0.024580076
B35: 4 | C35: PT Asuransi Allianz Life Syariah Indonesia | D35: 2014 | E35: =Data!N35 -> 0 | F35: =Data!G35 -> 0 | G35: =IFERROR(E35/F35,0) -> 0
D36: 2015 | E36: =Data!N36 -> 0 | F36: =Data!G36 -> 0 | G36: =IFERROR(E36/F36,0) -> 0
D37: 2016 | E37: =Data!N37 -> 0 | F37: =Data!G37 -> 0 | G37: =IFERROR(E37/F37,0) -> 0
D38: 2017 | E38: =Data!N38 -> 0 | F38: =Data!G38 -> 0 | G38: =IFERROR(E38/F38,0) -> 0
D39: 2018 | E39: =Data!N39 -> 0 | F39: =Data!G39 -> 0 | G39: =IFERROR(E39/F39,0) -> 0
D40: 2019 | E40: =Data!N40 -> 0 | F40: =Data!G40 -> 0 | G40: =IFERROR(E40/F40,0) -> 0
...

Sheet ROE
A1: Sub Sektor | B1: No | C1: Nama Perusahaan | D1: Tahun | E1: Laba Bersih | F1: Total Ekuitas | G1: Retun on Equity
A2: Asuransi Jiwa | B2: 1 | C2: Asuransi Jiwa Bersama Bumiputera 1912 | D2: 2014 | E2: =Data!N2 -> 0 | F2: =Data!K2 -> 0 | G2: =IFERROR(E2/F2,0) -> 0
D3: 2015 | E3: =Data!N3 -> 0 | F3: =Data!K3 -> 0 | G3: =IFERROR(E3/F3,0) -> 0
D4: 2016 | E4: =Data!N4 -> 0 | F4: =Data!K4 -> 0 | G4: =IFERROR(E4/F4,0) -> 0
D5: 2017 | E5: =Data!N5 -> 0 | F5: =Data!K5 -> 0 | G5: =IFERROR(E5/F5,0) -> 0
D6: 2018 | E6: =Data!N6 -> 0 | F6: =Data!K6 -> 0 | G6: =IFERROR(E6/F6,0) -> 0
D7: 2019 | E7: =Data!N7 -> 0 | F7: =Data!K7 -> 0 | G7: =IFERROR(E7/F7,0) -> 0
D8: 2020 | E8: =Data!N8 -> 0 | F8: =Data!K8 -> 0 | G8: =IFERROR(E8/F8,0) -> 0
D9: 2021 | E9: =Data!N9 -> 0 | F9: =Data!K9 -> 0 | G9: =IFERROR(E9/F9,0) -> 0
D10: 2022 | E10: =Data!N10 -> 0 | F10: =Data!K10 -> 0 | G10: =IFERROR(E10/F10,0) -> 0
D11: 2023 | E11: =Data!N11 -> 0 | F11: =Data!K11 -> 0 | G11: =IFERROR(E11/F11,0) -> 0
D12: 2024 | E12: =Data!N12 -> 0 | F12: =Data!K12 -> 0 | G12: =IFERROR(E12/F12,0) -> 0
B13: 2 | C13: PT AIA Financial | D13: 2014 | E13: =Data!N13 -> 0 | F13: =Data!K13 -> 0 | G13: =IFERROR(E13/F13,0) -> 0
D14: 2015 | E14: =Data!N14 -> 848437000000 | F14: =Data!K14 -> 6569253000000 | G14: =IFERROR(E14/F14,0) -> 0.12915274
D15: 2016 | E15: =Data!N15 -> 1197111000000 | F15: =Data!K15 -> 7766364000000 | G15: =IFERROR(E15/F15,0) -> 0.15414047
D16: 2017 | E16: =Data!N16 -> 1562417000000 | F16: =Data!K16 -> 10561914000000 | G16: =IFERROR(E16/F16,0) -> 0.14792934
D17: 2018 | E17: =Data!N17 -> 1065313000000 | F17: =Data!K17 -> 11027227000000 | G17: =IFERROR(E17/F17,0) -> 0.096607515
D18: 2019 | E18: =Data!N18 -> 2104310000000 | F18: =Data!K18 -> 11870589000000 | G18: =IFERROR(E18/F18,0) -> 0.1772709
D19: 2020 | E19: =Data!N19 -> -410562000000 | F19: =Data!K19 -> 11761575000000 | G19: =IFERROR(E19/F19,0) -> -0.03490706
D20: 2021 | E20: =Data!N20 -> -586757000000 | F20: =Data!K20 -> 11856333000000 | G20: =IFERROR(E20/F20,0) -> -0.04948891
D21: 2022 | E21: =Data!N21 -> -785208000000 | F21: =Data!K21 -> 8229889000000 | G21: =IFERROR(E21/F21,0) -> -0.095409306
D22: 2023 | E22: =Data!N22 -> 876769000000 | F22: =Data!K22 -> 8048626000000 | G22: =IFERROR(E22/F22,0) -> 0.108934
D23: 2024 | E23: =Data!N23 -> 1419919000000 | F23: =Data!K23 -> 8912301000000 | G23: =IFERROR(E23/F23,0) -> 0.15932126
B24: 3 | C24: PT Asuransi Allianz Life Indonesia | D24: 2014 | E24: =Data!N24 -> 0 | F24: =Data!K24 -> 0 | G24: =IFERROR(E24/F24,0) -> 0
D25: 2015 | E25: =Data!N25 -> 806099000000 | F25: =Data!K25 -> 4355995000000 | G25: =IFERROR(E25/F25,0) -> 0.18505508
D26: 2016 | E26: =Data!N26 -> 899890000000 | F26: =Data!K26 -> 5381290000000 | G26: =IFERROR(E26/F26,0) -> 0.1672257
D27: 2017 | E27: =Data!N27 -> 649699000000 | F27: =Data!K27 -> 6030989000000 | G27: =IFERROR(E27/F27,0) -> 0.10772678
D28: 2018 | E28: =Data!N28 -> 137111000000 | F28: =Data!K28 -> 5768100000000 | G28: =IFERROR(E28/F28,0) -> 0.023770566
D29: 2019 | E29: =Data!N29 -> 1493224000000 | F29: =Data!K29 -> 6511324000000 | G29: =IFERROR(E29/F29,0) -> 0.22932725
D30: 2020 | E30: =Data!N30 -> 1129656000000 | F30: =Data!K30 -> 7090980000000 | G30: =IFERROR(E30/F30,0) -> 0.15930887
D31: 2021 | E31: =Data!N31 -> 404045000000 | F31: =Data!K31 -> 6945025000000 | G31: =IFERROR(E31/F31,0) -> 0.058177616
D32: 2022 | E32: =Data!N32 -> 107318000000 | F32: =Data!K32 -> 7208812000000 | G32: =IFERROR(E32/F32,0) -> 0.014887058
D33: 2023 | E33: =Data!N33 -> 481260000000 | F33: =Data!K33 -> 6640072000000 | G33: =IFERROR(E33/F33,0) -> 0.07247813
D34: 2024 | E34: =Data!N34 -> 961867000000 | F34: =Data!K34 -> 7301939000000 | G34: =IFERROR(E34/F34,0) -> 0.13172761
B35: 4 | C35: PT Asuransi Allianz Life Syariah Indonesia | D35: 2014 | E35: =Data!N35 -> 0 | F35: =Data!K35 -> 0 | G35: =IFERROR(E35/F35,0) -> 0
D36: 2015 | E36: =Data!N36 -> 0 | F36: =Data!K36 -> 0 | G36: =IFERROR(E36/F36,0) -> 0
D37: 2016 | E37: =Data!N37 -> 0 | F37: =Data!K37 -> 0 | G37: =IFERROR(E37/F37,0) -> 0
D38: 2017 | E38: =Data!N38 -> 0 | F38: =Data!K38 -> 0 | G38: =IFERROR(E38/F38,0) -> 0
D39: 2018 | E39: =Data!N39 -> 0 | F39: =Data!K39 -> 0 | G39: =IFERROR(E39/F39,0) -> 0
D40: 2019 | E40: =Data!N40 -> 0 | F40: =Data!K40 -> 0 | G40: =IFERROR(E40/F40,0) -> 0
...

Sheet KM
A1: Sub Sektor | B1: No | C1: Nama Perusahaan | D1: Tahun | E1: Persentase Kepemilikan Terbesar | F1: Keterangan
A2: Asuransi Jiwa | B2: 1 | C2: Asuransi Jiwa Bersama Bumiputera 1912 | D2: 2014 | E2: =IFERROR(Data!O2,0) -> 0 | F2: =Data!P2 -> 0
D3: 2015 | E3: =Data!O3 -> 0 | F3: =Data!P3 -> 0
D4: 2016 | E4: =Data!O4 -> 0 | F4: =Data!P4 -> 0
D5: 2017 | E5: =Data!O5 -> 0 | F5: =Data!P5 -> 0
D6: 2018 | E6: =Data!O6 -> 0 | F6: =Data!P6 -> 0
D7: 2019 | E7: =Data!O7 -> 0 | F7: =Data!P7 -> 0
D8: 2020 | E8: =Data!O8 -> 0 | F8: =Data!P8 -> 0
D9: 2021 | E9: =Data!O9 -> 0 | F9: =Data!P9 -> 0
D10: 2022 | E10: =Data!O10 -> 0 | F10: =Data!P10 -> 0
D11: 2023 | E11: =Data!O11 -> 0 | F11: =Data!P11 -> 0
D12: 2024 | E12: =Data!O12 -> 0 | F12: =Data!P12 -> 0
B13: 2 | C13: PT AIA Financial | D13: 2014 | E13: =Data!O13 -> 0 | F13: =Data!P13 -> 0
D14: 2015 | E14: =Data!O14 -> 0.8 | F14: =Data!P14 -> AIA International Limited
D15: 2016 | E15: =Data!O15 -> 0.8 | F15: =Data!P15 -> AIA International Limited
D16: 2017 | E16: =Data!O16 -> 0.95 | F16: =Data!P16 -> AIA International Limited
D17: 2018 | E17: =Data!O17 -> 0.95 | F17: =Data!P17 -> AIA International Limited
D18: 2019 | E18: =Data!O18 -> 0.9499 | F18: =Data!P18 -> AIA International Limited
D19: 2020 | E19: =Data!O19 -> 0.9499 | F19: =Data!P19 -> AIA International Limited
D20: 2021 | E20: =Data!O20 -> 0.9499 | F20: =Data!P20 -> AIA International Limited
D21: 2022 | E21: =Data!O21 -> 0.9499 | F21: =Data!P21 -> AIA International Limited
D22: 2023 | E22: =Data!O22 -> 0.9499 | F22: =Data!P22 -> AIA International Limited
D23: 2024 | E23: =Data!O23 -> 0.9499 | F23: =Data!P23 -> AIA International Limited
B24: 3 | C24: PT Asuransi Allianz Life Indonesia | D24: 2014 | E24: =Data!O24 -> 0 | F24: =Data!P24 -> 0
D25: 2015 | E25: =Data!O25 -> 0.9976 | F25: =Data!P25 -> Allianz Asia Pacific & Africa GmbH
D26: 2016 | E26: =Data!O26 -> 0.9976 | F26: =Data!P26 -> Allianz Asia Pacific & Africa GmbH
D27: 2017 | E27: =Data!O27 -> 0.9976 | F27: =Data!P27 -> Allianz Asia Pacific & Africa GmbH
D28: 2018 | E28: =Data!O28 -> 0.9976 | F28: =Data!P28 -> Allianz Asia Pacific & Africa GmbH
D29: 2019 | E29: =Data!O29 -> 0.9976 | F29: =Data!P29 -> Allianz Asia Pacific & Africa GmbH
D30: 2020 | E30: =Data!O30 -> 0.9976 | F30: =Data!P30 -> Allianz Asia Pacific & Africa GmbH
D31: 2021 | E31: =Data!O31 -> 0.9976 | F31: =Data!P31 -> Allianz Asia Pacific & Africa GmbH
D32: 2022 | E32: =Data!O32 -> 0.9976 | F32: =Data!P32 -> Allianz Asia Pacific & Africa GmbH
D33: 2023 | E33: =Data!O33 -> 0.9976 | F33: =Data!P33 -> Allianz Asia Pacific & Africa GmbH
D34: 2024 | E34: =Data!O34 -> 0.9976 | F34: =Data!P34 -> Allianz Asia Pacific & Africa GmbH
B35: 4 | C35: PT Asuransi Allianz Life Syariah Indonesia | D35: 2014 | E35: =Data!O35 -> 0 | F35: =Data!P35 -> 0
D36: 2015 | E36: =Data!O36 -> 0 | F36: =Data!P36 -> 0
D37: 2016 | E37: =Data!O37 -> 0 | F37: =Data!P37 -> 0
D38: 2017 | E38: =Data!O38 -> 0 | F38: =Data!P38 -> 0
D39: 2018 | E39: =Data!O39 -> 0 | F39: =Data!P39 -> 0
D40: 2019 | E40: =Data!O40 -> 0 | F40: =Data!P40 -> 0
...

Sheet KI
A1: Sub Sektor | B1: No | C1: Nama Perusahaan | D1: Tahun | E1: Jumlah Komisaris Independen
A2: Asuransi Jiwa | B2: 1 | C2: Asuransi Jiwa Bersama Bumiputera 1912 | D2: 2014 | E2: =Data!Q2 -> 0
D3: 2015 | E3: =Data!Q3 -> 0
D4: 2016 | E4: =Data!Q4 -> 0
D5: 2017 | E5: =Data!Q5 -> 0
D6: 2018 | E6: =Data!Q6 -> 0
D7: 2019 | E7: =Data!Q7 -> 0
D8: 2020 | E8: =Data!Q8 -> 0
D9: 2021 | E9: =Data!Q9 -> 0
D10: 2022 | E10: =Data!Q10 -> 0
D11: 2023 | E11: =Data!Q11 -> 0
D12: 2024 | E12: =Data!Q12 -> 0
B13: 2 | C13: PT AIA Financial | D13: 2014 | E13: =Data!Q13 -> 0
D14: 2015 | E14: =Data!Q14 -> 2
D15: 2016 | E15: =Data!Q15 -> 2
D16: 2017 | E16: =Data!Q16 -> 2
D17: 2018 | E17: =Data!Q17 -> 2
D18: 2019 | E18: =Data!Q18 -> 2
D19: 2020 | E19: =Data!Q19 -> 2
D20: 2021 | E20: =Data!Q20 -> 1
D21: 2022 | E21: =Data!Q21 -> 1
D22: 2023 | E22: =Data!Q22 -> 2
D23: 2024 | E23: =Data!Q23 -> 1
B24: 3 | C24: PT Asuransi Allianz Life Indonesia | D24: 2014 | E24: =Data!Q24 -> 0
D25: 2015 | E25: =Data!Q25 -> 2
D26: 2016 | E26: =Data!Q26 -> 2
D27: 2017 | E27: =Data!Q27 -> 2
D28: 2018 | E28: =Data!Q28 -> 2
D29: 2019 | E29: =Data!Q29 -> 2
D30: 2020 | E30: =Data!Q30 -> 2
D31: 2021 | E31: =Data!Q31 -> 2
D32: 2022 | E32: =Data!Q32 -> 2
D33: 2023 | E33: =Data!Q33 -> 2
D34: 2024 | E34: =Data!Q34 -> 2
B35: 4 | C35: PT Asuransi Allianz Life Syariah Indonesia | D35: 2014 | E35: =Data!Q35 -> 0
D36: 2015 | E36: =Data!Q36 -> 0
D37: 2016 | E37: =Data!Q37 -> 0
D38: 2017 | E38: =Data!Q38 -> 0
D39: 2018 | E39: =Data!Q39 -> 0
D40: 2019 | E40: =Data!Q40 -> 0
...

Sheet IO
A1: Sub Sektor | B1: No | C1: Nama Perusahaan | D1: Tahun | E1: Persentase Kepemilikan oleh Komisaris dan Direksi
A2: Asuransi Jiwa | B2: 1 | C2: Asuransi Jiwa Bersama Bumiputera 1912 | D2: 2014 | E2: =Data!U2 -> 0
D3: 2015 | E3: =Data!U3 -> 0
D4: 2016 | E4: =Data!U4 -> 0
D5: 2017 | E5: =Data!U5 -> 0
D6: 2018 | E6: =Data!U6 -> 0
D7: 2019 | E7: =Data!U7 -> 0
D8: 2020 | E8: =Data!U8 -> 0
D9: 2021 | E9: =Data!U9 -> 0
D10: 2022 | E10: =Data!U10 -> 0
D11: 2023 | E11: =Data!U11 -> 0
D12: 2024 | E12: =Data!U12 -> 0
B13: 2 | C13: PT AIA Financial | D13: 2014 | E13: =Data!U13 -> 0
D14: 2015 | E14: =Data!U14 -> 0
D15: 2016 | E15: =Data!U15 -> 0
D16: 2017 | E16: =Data!U16 -> 0
D17: 2018 | E17: =Data!U17 -> 0
D18: 2019 | E18: =Data!U18 -> 0
D19: 2020 | E19: =Data!U19 -> 0
D20: 2021 | E20: =Data!U20 -> 0
D21: 2022 | E21: =Data!U21 -> 0
D22: 2023 | E22: =Data!U22 -> 0
D23: 2024 | E23: =Data!U23 -> 0
B24: 3 | C24: PT Asuransi Allianz Life Indonesia | D24: 2014 | E24: =Data!U24 -> 0
D25: 2015 | E25: =Data!U25 -> 0
D26: 2016 | E26: =Data!U26 -> 0
D27: 2017 | E27: =Data!U27 -> 0
D28: 2018 | E28: =Data!U28 -> 0
D29: 2019 | E29: =Data!U29 -> 0
D30: 2020 | E30: =Data!U30 -> 0
D31: 2021 | E31: =Data!U31 -> 0
D32: 2022 | E32: =Data!U32 -> 0
D33: 2023 | E33: =Data!U33 -> 0
D34: 2024 | E34: =Data!U34 -> 0
B35: 4 | C35: PT Asuransi Allianz Life Syariah Indonesia | D35: 2014 | E35: =Data!U35 -> 0
D36: 2015 | E36: =Data!U36 -> 0
D37: 2016 | E37: =Data!U37 -> 0
D38: 2017 | E38: =Data!U38 -> 0
D39: 2018 | E39: =Data!U39 -> 0
D40: 2019 | E40: =Data!U40 -> 0
...

Sheet BoC Size
A1: Sub Sektor | B1: No | C1: Nama Perusahaan | D1: Tahun | E1: Jumlah Dewan Komisaris
A2: Asuransi Jiwa | B2: 1 | C2: Asuransi Jiwa Bersama Bumiputera 1912 | D2: 2014 | E2: =Data!R2 -> 0
D3: 2015 | E3: =Data!R3 -> 0
D4: 2016 | E4: =Data!R4 -> 0
D5: 2017 | E5: =Data!R5 -> 0
D6: 2018 | E6: =Data!R6 -> 0
D7: 2019 | E7: =Data!R7 -> 0
D8: 2020 | E8: =Data!R8 -> 0
D9: 2021 | E9: =Data!R9 -> 0
D10: 2022 | E10: =Data!R10 -> 0
D11: 2023 | E11: =Data!R11 -> 0
D12: 2024 | E12: =Data!R12 -> 0
B13: 2 | C13: PT AIA Financial | D13: 2014 | E13: =Data!R13 -> 0
D14: 2015 | E14: =Data!R14 -> 4
D15: 2016 | E15: =Data!R15 -> 4
D16: 2017 | E16: =Data!R16 -> 4
D17: 2018 | E17: =Data!R17 -> 4
D18: 2019 | E18: =Data!R18 -> 4
D19: 2020 | E19: =Data!R19 -> 4
D20: 2021 | E20: =Data!R20 -> 3
D21: 2022 | E21: =Data!R21 -> 3
D22: 2023 | E22: =Data!R22 -> 4
D23: 2024 | E23: =Data!R23 -> 3
B24: 3 | C24: PT Asuransi Allianz Life Indonesia | D24: 2014 | E24: =Data!R24 -> 0
D25: 2015 | E25: =Data!R25 -> 3
D26: 2016 | E26: =Data!R26 -> 3
D27: 2017 | E27: =Data!R27 -> 4
D28: 2018 | E28: =Data!R28 -> 3
D29: 2019 | E29: =Data!R29 -> 3
D30: 2020 | E30: =Data!R30 -> 3
D31: 2021 | E31: =Data!R31 -> 4
D32: 2022 | E32: =Data!R32 -> 3
D33: 2023 | E33: =Data!R33 -> 4
D34: 2024 | E34: =Data!R34 -> 4
B35: 4 | C35: PT Asuransi Allianz Life Syariah Indonesia | D35: 2014 | E35: =Data!R35 -> 0
D36: 2015 | E36: =Data!R36 -> 0
D37: 2016 | E37: =Data!R37 -> 0
D38: 2017 | E38: =Data!R38 -> 0
D39: 2018 | E39: =Data!R39 -> 0
D40: 2019 | E40: =Data!R40 -> 0
...

Sheet TMT E DK
A1: Sub Sektor | B1: No | C1: Nama Perusahaan | D1: Tahun | E1: TMT Education (Dewan Komisaris)
A2: Asuransi Jiwa | B2: 1 | C2: Asuransi Jiwa Bersama Bumiputera 1912 | D2: 2014 | E2: =Data!V2 -> 0
D3: 2015 | E3: =Data!V3 -> 0
D4: 2016 | E4: =Data!V4 -> 0
D5: 2017 | E5: =Data!V5 -> 0
D6: 2018 | E6: =Data!V6 -> 0
D7: 2019 | E7: =Data!V7 -> 0
D8: 2020 | E8: =Data!V8 -> 0
D9: 2021 | E9: =Data!V9 -> 0
D10: 2022 | E10: =Data!V10 -> 0
D11: 2023 | E11: =Data!V11 -> 0
D12: 2024 | E12: =Data!V12 -> 0
B13: 2 | C13: PT AIA Financial | D13: 2014 | E13: =Data!V13 -> 0
D14: 2015 | E14: =Data!V14 -> 0
D15: 2016 | E15: =Data!V15 -> 0
D16: 2017 | E16: =Data!V16 -> 0
D17: 2018 | E17: =Data!V17 -> 0
D18: 2019 | E18: =Data!V18 -> 0
D19: 2020 | E19: =Data!V19 -> 0
D20: 2021 | E20: =Data!V20 -> 0
D21: 2022 | E21: =Data!V21 -> 0
D22: 2023 | E22: =Data!V22 -> 0
D23: 2024 | E23: =Data!V23 -> 0
B24: 3 | C24: PT Asuransi Allianz Life Indonesia | D24: 2014 | E24: =Data!V24 -> 0
D25: 2015 | E25: =Data!V25 -> 0
D26: 2016 | E26: =Data!V26 -> 0
D27: 2017 | E27: =Data!V27 -> 0
D28: 2018 | E28: =Data!V28 -> 0
D29: 2019 | E29: =Data!V29 -> 0
D30: 2020 | E30: =Data!V30 -> 8
D31: 2021 | E31: =Data!V31 -> 9
D32: 2022 | E32: =Data!V32 -> 8
D33: 2023 | E33: =Data!V33 -> 8
D34: 2024 | E34: =Data!V34 -> 8
B35: 4 | C35: PT Asuransi Allianz Life Syariah Indonesia | D35: 2014 | E35: =Data!V35 -> 0
D36: 2015 | E36: =Data!V36 -> 0
D37: 2016 | E37: =Data!V37 -> 0
D38: 2017 | E38: =Data!V38 -> 0
D39: 2018 | E39: =Data!V39 -> 0
D40: 2019 | E40: =Data!V40 -> 0
...

Sheet TMT E DD
A1: Sub Sektor | B1: No | C1: Nama Perusahaan | D1: Tahun | E1: TMT Education (Dewan Direksi)
A2: Asuransi Jiwa | B2: 1 | C2: Asuransi Jiwa Bersama Bumiputera 1912 | D2: 2014 | E2: =Data!X2 -> 0
D3: 2015 | E3: =Data!X3 -> 0
D4: 2016 | E4: =Data!X4 -> 0
D5: 2017 | E5: =Data!X5 -> 0
D6: 2018 | E6: =Data!X6 -> 0
D7: 2019 | E7: =Data!X7 -> 0
D8: 2020 | E8: =Data!X8 -> 0
D9: 2021 | E9: =Data!X9 -> 0
D10: 2022 | E10: =Data!X10 -> 0
D11: 2023 | E11: =Data!X11 -> 0
D12: 2024 | E12: =Data!X12 -> 0
B13: 2 | C13: PT AIA Financial | D13: 2014 | E13: =Data!X13 -> 0
D14: 2015 | E14: =Data!X14 -> 0
D15: 2016 | E15: =Data!X15 -> 0
D16: 2017 | E16: =Data!X16 -> 0
D17: 2018 | E17: =Data!X17 -> 0
D18: 2019 | E18: =Data!X18 -> 0
D19: 2020 | E19: =Data!X19 -> 0
D20: 2021 | E20: =Data!X20 -> 0
D21: 2022 | E21: =Data!X21 -> 0
D22: 2023 | E22: =Data!X22 -> 0
D23: 2024 | E23: =Data!X23 -> 0
B24: 3 | C24: PT Asuransi Allianz Life Indonesia | D24: 2014 | E24: =Data!X24 -> 0
D25: 2015 | E25: =Data!X25 -> 0
D26: 2016 | E26: =Data!X26 -> 0
D27: 2017 | E27: =Data!X27 -> 0
D28: 2018 | E28: =Data!X28 -> 0
D29: 2019 | E29: =Data!X29 -> 0
D30: 2020 | E30: =Data!X30 -> 14
D31: 2021 | E31: =Data!X31 -> 11
D32: 2022 | E32: =Data!X32 -> 8
D33: 2023 | E33: =Data!X33 -> 10
D34: 2024 | E34: =Data!X34 -> 6
B35: 4 | C35: PT Asuransi Allianz Life Syariah Indonesia | D35: 2014 | E35: =Data!X35 -> 0
D36: 2015 | E36: =Data!X36 -> 0
D37: 2016 | E37: =Data!X37 -> 0
D38: 2017 | E38: =Data!X38 -> 0
D39: 2018 | E39: =Data!X39 -> 0
D40: 2019 | E40: =Data!X40 -> 0
...

Sheet TMT Size
A1: Sub Sektor | B1: No | C1: Nama Perusahaan | D1: Tahun | E1: Jumlah Dewan Komisaris dan Jumlah Dewan Direksi
A2: Asuransi Jiwa | B2: 1 | C2: Asuransi Jiwa Bersama Bumiputera 1912 | D2: 2014 | E2: =Data!T2 -> 0
D3: 2015 | E3: =Data!T3 -> 0
D4: 2016 | E4: =Data!T4 -> 0
D5: 2017 | E5: =Data!T5 -> 0
D6: 2018 | E6: =Data!T6 -> 0
D7: 2019 | E7: =Data!T7 -> 0
D8: 2020 | E8: =Data!T8 -> 0
D9: 2021 | E9: =Data!T9 -> 0
D10: 2022 | E10: =Data!T10 -> 0
D11: 2023 | E11: =Data!T11 -> 0
D12: 2024 | E12: =Data!T12 -> 0
B13: 2 | C13: PT AIA Financial | D13: 2014 | E13: =Data!T13 -> 0
D14: 2015 | E14: =Data!T14 -> 9
D15: 2016 | E15: =Data!T15 -> 9
D16: 2017 | E16: =Data!T16 -> 9
D17: 2018 | E17: =Data!T17 -> 9
D18: 2019 | E18: =Data!T18 -> 8
D19: 2020 | E19: =Data!T19 -> 8
D20: 2021 | E20: =Data!T20 -> 7
D21: 2022 | E21: =Data!T21 -> 7
D22: 2023 | E22: =Data!T22 -> 9
D23: 2024 | E23: =Data!T23 -> 8
B24: 3 | C24: PT Asuransi Allianz Life Indonesia | D24: 2014 | E24: =Data!T24 -> 0
D25: 2015 | E25: =Data!T25 -> 7
D26: 2016 | E26: =Data!T26 -> 7
D27: 2017 | E27: =Data!T27 -> 9
D28: 2018 | E28: =Data!T28 -> 9
D29: 2019 | E29: =Data!T29 -> 9
D30: 2020 | E30: =Data!T30 -> 9
D31: 2021 | E31: =Data!T31 -> 9
D32: 2022 | E32: =Data!T32 -> 7
D33: 2023 | E33: =Data!T33 -> 8
D34: 2024 | E34: =Data!T34 -> 7
B35: 4 | C35: PT Asuransi Allianz Life Syariah Indonesia | D35: 2014 | E35: =Data!T35 -> 0
D36: 2015 | E36: =Data!T36 -> 0
D37: 2016 | E37: =Data!T37 -> 0
D38: 2017 | E38: =Data!T38 -> 0
D39: 2018 | E39: =Data!T39 -> 0
D40: 2019 | E40: =Data!T40 -> 0
...

Sheet TA
A1: Sub Sektor | B1: No | C1: Nama Perusahaan | D1: Tahun | E1: Total Aset
A2: Asuransi Jiwa | B2: 1 | C2: Asuransi Jiwa Bersama Bumiputera 1912 | D2: 2014 | E2: =Data!G2 -> 0
D3: 2015 | E3: =Data!G3 -> 0
D4: 2016 | E4: =Data!G4 -> 0
D5: 2017 | E5: =Data!G5 -> 0
D6: 2018 | E6: =Data!G6 -> 0
D7: 2019 | E7: =Data!G7 -> 0
D8: 2020 | E8: =Data!G8 -> 0
D9: 2021 | E9: =Data!G9 -> 0
D10: 2022 | E10: =Data!G10 -> 0
D11: 2023 | E11: =Data!G11 -> 0
D12: 2024 | E12: =Data!G12 -> 0
B13: 2 | C13: PT AIA Financial | D13: 2014 | E13: =Data!G13 -> 0
D14: 2015 | E14: =Data!G14 -> 31860954000000
D15: 2016 | E15: =Data!G15 -> 35767906000000
D16: 2017 | E16: =Data!G16 -> 44937292000000
D17: 2018 | E17: =Data!G17 -> 46562563000000
D18: 2019 | E18: =Data!G18 -> 50043024000000
D19: 2020 | E19: =Data!G19 -> 53134780000000
D20: 2021 | E20: =Data!G20 -> 52330016000000
D21: 2022 | E21: =Data!G21 -> 44912325000000
D22: 2023 | E22: =Data!G22 -> 41785302000000
